Workbook
Name ItemTotal: Schedule!$G$4254
Name MRItemTotal: Schedule!$G$4256
Name SRItemTotal: Schedule!$G$4255

Sheet Abstract
A1: ABSTRACT OF COST | F1: =Schedule!G4255 -> 12497954
A2: Name of the work : DSR - 2023 IN MS EXCEL
A4: S.H. No. | B4: Description of Sub-Head | D4: Amount (Rs)
A6: 01. | B6: Earth Work | C6: : | D6: =Schedule!G119 -> 76358
A7: 02. | B7: Concrete Work | C7: : | D7: =Schedule!G217 -> 480106
A8: 03. | B8: Reinforced Cement Concrete | C8: : | D8: =Schedule!G391 -> 839767
A9: 04. | B9: Masonry Work | C9: : | D9: =Schedule!G468 -> 390279
A10: 05. | B10: Stone Work | C10: : | D10: =Schedule!G553 -> 2195632
A11: 06. | B11: Cladding Work | C11: : | D11: =Schedule!G658 -> 454723
A12: 07. | B12: Wood and P.V.C. Work | C12: : | D12: =Schedule!G1200 -> 1941900
A13: 08. | B13: Steel Work | C13: : | D13: =Schedule!G1272 -> 56882
A14: 09. | B14: Flooring | C14: : | D14: =Schedule!G1451 -> 242519
A15: 10. | B15: Roofing | C15: : | D15: =Schedule!G1655 -> 118019
A16: 11. | B16: Finishing | C16: : | D16: =Schedule!G1885 -> 35733
A17: 12. | B17: Repairs to Buildings | C17: : | D17: =Schedule!G2024 -> 693389
A18: 13. | B18: Dismantling and Demolishing | C18: : | D18: =Schedule!G2143 -> 82595
A19: 14. | B19: Road Work | C19: : | D19: =Schedule!G2337 -> 382465
A20: 15. | B20: Sanitary Installations | C20: : | D20: =Schedule!G2677 -> 549669
A21: 16. | B21: Water Supply | C21: : | D21: =Schedule!G3505 -> 1952347
A22: 17. | B22: Drainage | C22: : | D22: =Schedule!G3684 -> 820929
A23: 18. | B23: Pile Work | C23: : | D23: =Schedule!G3747 -> 655287
A24: 19. | B24: Aluminium Work | C24: : | D24: =Schedule!G3805 -> 36680
A25: 20. | B25: Water Proofing | C25: : | D25: =Schedule!G3866 -> 54919
A26: 21. | B26: Rain Water Harvesting and Tube Well | C26: : | D26: =Schedule!G3920 -> 51686
A27: 22. | B27: Conservation of Heritage Buildings | C27: : | D27: =Schedule!G3933 -> 1886
A28: 23. | B28: Structural Glazing and Aluminium Co | C28: : | D28: =Schedule!G3948 -> 25428
A29: 24. | B29: New Technologies and Materials | C29: : | D29: =Schedule!G4252 -> 358756
B30: Total : | C30: : | D30: =SUM(D6:D29) -> 12497954 | F30: =D30-F1 -> 0
B31: Add GST @ 18.00% on (A) | C31: : | D31: =ROUND(D30*18%,0) -> 2249632
B32: Add contingencies @ 5% on (A) | C32: : | D32: =ROUND(D30*5%,0) -> 624898
B33: Grand Total | D33: =SUM(D30:D32) -> 15372484
B35: Say | D35: =ROUND((D33+30)/100,0)*100 -> 15372500
B40: Junior Telecom Officer (Civil) | C40: Sub-Divisional Engineer (Civil)
B41: BSNL Civil Sub-Division | C41: BSNL Civil Sub-Division
B42: NALGONDA | C42: NALGONDA
C48: Executive Engineer (Civil)
C49: BSNL Civil Dn-I
C50: HYDERABAD

Sheet Schedule
A1: SCHEDULE OF QUANTITIES
B2: Name of the work : DSR - 2023 IN MS EXCEL
A3: I.No. | B3: Description of Item | C3: Quantity | E3: Rate (Rs) | F3: Unit | G3: Amount(Rs)
A4: Sub-Head : Earth Work
A5: 2.1 | B5: Earth work in surface excavation not exceeding 30 cm in depth but exceeding 1.5 m in width as well as 10 sqm on plan including getting out and disposal of excavated earth upto 50 m and lift up to 1.5 m, as directed by Engineer-in-Charge: | H5: Earth work in surface excavation:
A6: 2.1.1 | B6: All kinds of soil | C6: 1 | D6: Sqm | E6: 129.85 | F6: One Square Metre | G6: =ROUND(C6*E6,0) -> 130 | H6: All kinds of soil.
A7: 2.2 | B7: Earth work by mechinical / manual means in rough excavation, banking excavated earth in layers not exceeding 20cm in depth, breaking clods, watering, rolling each layer with 'A tonne roller or wooden or steel rammers, and rolling every 3rd and top-most layer with power roller of minimum 8 tonnes and dressing up in embankments for roads, flood banks, marginal banks and guide banks or filling up ground depressions, lead upto 50 m and for all lift | H7: Earth work in rough excavation, banking excavated earth :
A8: 2.2.1 | B8: All kinds of soil | C8: 1 | D8: Cum | E8: 395.3 | F8: One Cubic Metre | G8: =ROUND(C8*E8,0) -> 395 | H8: All kinds of soil.
A9: 2.3 | B9: Banking excavated earth by mechanical / manual means in layers not exceeding 20 cm in depth, breaking clods, watering, rolling each layer with 'A tonne roller, or wooden or steel rammers, and roiling every 3rd and top-most layer with power roller of minimum 8 tonnes and dressing up, in embankments for roads, flood banks, marginal banks, and guide banks etc, lead upto 50 m and for all lift: | H9: Banking excavated earth in layers not exceeding 20 cm. in depth, breaking clods :-
A10: 2.3.1 | B10: All kinds of soil | C10: 1 | D10: Cum | E10: 197.9 | F10: One Cubic Metre | G10: =ROUND(C10*E10,0) -> 198 | H10: All kinds of soil.
A11: 2.4 | B11: Deduct for not rolling with power roller of minimum 8 tonnes for banking excavated earth in layers not exceeding 20 cm in depth. | C11: 1 | D11: Cum | E11: -5.25 | F11: One Cubic Metre | G11: =ROUND(C11*E11,0) -> -5 | H11: Deduct for not rolling with power roller.
A12: 2.5 | B12: Deduct for not watering the excavated earth for banking | C12: 1 | D12: Cum | E12: -14.25 | F12: One Cubic Metre | G12: =ROUND(C12*E12,0) -> -14 | H12: Deduct for not watering the excavated earth for banking.
A13: 2.6 | B13: Earth work in excavation by mechanical means (Hydraulic excavator) / manual means over areas (exceeding 30cm in depth, 1.5m in width as well as 10 sqm on plan) including getting out and disposal of excavated earth, lead up to 50m and lift up to 1.5m,as directed by Engineer-in-Charge. | H13: Earth work in excavation over areas :-
A14: 2.6.1 | B14: All kinds of soil | C14: 1 | D14: Cum | E14: 177.5 | F14: One Cubic Metre | G14: =ROUND(C14*E14,0) -> 178 | H14: All kinds of soil .
A15: 2.7 | B15: Earth work in excavation by mechanical means (Hydraulic excavator) / manual means over areas (exceeding 30 cm in depth, 1.5m in width as well as 10 sqm on plan) including getting out and disposal of excavated earth, lead up to 50 m and lift up to 1.5m, as directed by Engineer-in-Charge. | H15: Earth work in excavation over areas :-
A16: 2.7.1 | B16: Ordinary rock | C16: 1 | D16: Cum | E16: 498.9 | F16: One Cubic Metre | G16: =ROUND(C16*E16,0) -> 499 | H16: Ordinary rock.
A17: 2.7.2 | B17: Hard rock (requiring blasting) | C17: 1 | D17: Cum | E17: 874.4 | F17: One Cubic Metre | G17: =ROUND(C17*E17,0) -> 874 | H17: Hard rock (requ blasting).
A18: 2.7.3 | B18: Hard rock (blasting prohibited) | C18: 1 | D18: Cum | E18: 1432.95 | F18: One Cubic Metre | G18: =ROUND(C18*E18,0) -> 1433 | H18: Hard rock (blasting prohi).
A19: 2.8 | B19: Earth work in excavation by mechanical means (Hydraulic excavator) / manual means in foundation trenches or drains (not exceeding 1.5 m in width or 10 sqm on plan) including dressing of sides and ramming of bottoms, lift up to 1.5 m, including getting out the excavated soil and disposal of surplus excavated soil as directed, within a lead of 50 m. | H19: E/W in excavation in foundation trenches :-
A20: 2.8.1 | B20: All kinds of soil. | C20: 1 | D20: Cum | E20: 260.3 | F20: One Cubic Metre | G20: =ROUND(C20*E20,0) -> 260 | H20: All kinds of soil.
A21: 2.9 | B21: Excavation work by mechanical means (Hydraulic excavator)/ manual means in foundation trenches or drains (not exceeding 1.5m in width or 10 sqm on plan) including dressing of sides and ramming of bottoms, lift up to 1.5 m, including getting out the excavated soil and disposal of surplus excavated soils as directed, within a lead of 50m. | H21: Excavation work in foundation, trenches :-
A22: 2.9.1 | B22: Ordinary rock | C22: 1 | D22: Cum | E22: 632.95 | F22: One Cubic Metre | G22: =ROUND(C22*E22,0) -> 633 | H22: Ordinary rock.
A23: 2.9.2 | B23: Hard rock (requiring blasting) | C23: 1 | D23: Cum | E23: 1049.8 | F23: One Cubic Metre | G23: =ROUND(C23*E23,0) -> 1050 | H23: Hard rock (requ blasting).
A24: 2.9.3 | B24: Hard rock (blasting prohibited) | C24: 1 | D24: Cum | E24: 1523.05 | F24: One Cubic Metre | G24: =ROUND(C24*E24,0) -> 1523 | H24: Hard rock (blasting probi).
A25: 2.10 | B25: Excavating trenches of required width for pipes, cables, etc including excavation for sockets, and dressing of sides, ramming of bottoms, depth up to 1.5 m, including getting out the excavated soil, and then returning the soil as required, in layers not exceeding 20 cm in depth, including consolidating each deposited layer by ramming, watering, etc. and disposing of surplus excavated soil as directed, within a lead of 50 m : | H25: Excavating trenches for pipes , cables
A26: 2.10.1 | B26: All kinds of soil | H26: All kinds of soil
A27: 2.10.1.1 | B27: Pipes, cables etc, not exceeding 80 mm dia. | C27: 1 | D27: Nos | E27: 215.6 | F27: One Metre | G27: =ROUND(C27*E27,0) -> 216 | H27: Pipes upto 80 mm dia.
A28: 2.10.1.2 | B28: Pipes, cables etc. exceeding 80 mm dia. but not exceeding 300 mm dia | C28: 1 | D28: Nos | E28: 352.15 | F28: One Metre | G28: =ROUND(C28*E28,0) -> 352 | H28: Pipes, cables etc. exceeding 80 mm dia. but not exceeding 300 mm dia
A29: 2.10.1.3 | B29: Pipes, cables etc. exceeding 300 mm dia but not exceeding 600 mm. | C29: 1 | D29: Nos | E29: 549.75 | F29: One Metre | G29: =ROUND(C29*E29,0) -> 550 | H29: Pipes , cables 300 to 600 mm.
A30: 2.13 | B30: Excavating trenches of required width for pipes, cables, etc, including excavation for sockets, depth up to 1.5 m, including getting out the excavated materials, returning the soil as required in layers not exceeding 20 cm in depth, including consolidating each deposited layers by ramming, watering etc., stacking serviceable material for measurements and disposal of unserviceable material as directed, within a lead of 50m : | H30: Excavating trenches for pipes cables
A31: 2.13.1 | B31: Ordinary rock : | H31: Ordinary rocks :
A32: 2.13.1.1 | B32: Pipes, cables etc. not exceeding 80 mm dia. | C32: 1 | D32: Nos | E32: 403.3 | F32: One Metre | G32: =ROUND(C32*E32,0) -> 403 | H32: Pipes, upto 80 mm dia.
A33: 2.13.1.2 | B33: Pipes, cables etc. exceeding 80 mm dia but not exceeding 300 mm dia. | C33: 1 | D33: Nos | E33: 998.65 | F33: One Metre | G33: =ROUND(C33*E33,0) -> 999 | H33: Pipes, 80 mm to 300 mm dia.
A34: 2.13.1.3 | B34: Pipes, cables exceeding 300 mm dia but not exceeding 600mm dia | C34: 1 | D34: Nos | E34: 1149.1 | F34: One Metre | G34: =ROUND(C34*E34,0) -> 1149 | H34: Pipes 300 to 600 mm. dia
A35: 2.13.2 | B35: Hard rock (requiring blasting) | H35: Hard rock (requi blasting) :
A36: 2.13.2.1 | B36: Pipes, cables etc. not exceeding 80 mm dia. | C36: 1 | D36: Nos | E36: 603.2 | F36: One Metre | G36: =ROUND(C36*E36,0) -> 603 | H36: Pipes, upto 80 mm dia.
A37: 2.13.2.2 | B37: Pipes, cables etc. exceeding 80 mm dia. but not exceeding 300 mm dia. | C37: 1 | D37: Nos | E37: 1493.6 | F37: One Metre | G37: =ROUND(C37*E37,0) -> 1494 | H37: Pipes 80 mm to 300 mm dia.
A38: 2.13.2.3 | B38: Pipes, cables etc. exceeding 300 mm dia but not exceeding 600mm dia | C38: 1 | D38: Nos | E38: 1718.45 | F38: One Metre | G38: =ROUND(C38*E38,0) -> 1718 | H38: Pipes 300 to 600 mm.
A39: 2.13.3 | B39: Hard rock (blasting prohibited) | H39: Hard rock (blasting prohi) :
A40: 2.13.3.1 | B40: Pipes, cables etc. not exceeding 80 mm dia. | C40: 1 | D40: Nos | E40: 826.8 | F40: One Metre | G40: =ROUND(C40*E40,0) -> 827 | H40: Pipes upto 80 mm dia.
...

Sheet ReadMe
A1: DSR 2023 IN MS EXCEL WITH FORMULAS (Updated on 30.11.2023)
A2: Read Me
A3: 01. | B3: This is a estimate proforma containing all the items of CPWD published DSR-2023, generated using Jalli's App - 2023.
A4: 02. | B4: Data has been compiled and verified by many Engineers from BSNL and other Departments and from all over India (see the table below)
A5: 03. | B5: Though, the data has been verified thoroughly, this file may contain certain mistakes/omissions.
B6: Hence, the users of this file are advised to verify the correctness of the data with original DSR-2023 and Correction Slips (if any) published by CPWD.
A7: 04. | B7: Neither the author/publisher nor his associates, who compiled or verified the data for this file, are responsible for the damages/ losses whatsoever may be, that may occur directly or indirectly due to the incorrect data of this file.
A8: 05. | B8: This is not a replica of DSR-2023 published by the CPWD, but a standard Detailed Estimate Proforma which is normally used in Civil Engineering Departments of various Central / State Government or PSUs.
A9: 06. | B9: Please drop an e-mail to me at rambabujalli@gmail.com for any queries regarding this file and confine your querry to this file only.
A10: 07. | B10: This file will be updated as and when errors are noticed and the file is corrected / CS is released for DSR-2023, keep visiting our website www.jallisapp.com to download the updated version.
B12: On behalf of all , my Sincere thanks to the following Officers who compiled / verified the data for making this file!
B14: Participated in compiling the data Sri / Smt
A15: 1 | B15: Nurul Haque, Kolkata
A16: 2 | B16: Sabya sachi mitra, Kolkata
A17: 3 | B17: Vijay Prakah Sharma, Ranchi, Jharkhand.
A18: 4 | B18: CRR Varma, Hyderabad, TS
A19: 5 | B19: G.Ashok Kumar, AP
A20: 6 | B20: K.Lakshmana Babu, Visakhapatnam, AP
A21: 7 | B21: Anurag Mishra, Gorakhpur UP.
A22: 8 | B22: Nandini Moorthy, Chennai
A23: 9 | B23: Kondal Rao P, Vijayawada, AP
A24: 10 | B24: K.Senthil Velan, TN
A25: 11 | B25: Anil Jotani, Rajkot, GJ.
A26: 12 | B26: Jitendra Singh, Kolkata.
... A38: 27 | B38: Yogendra Kumar
B45: -Rambabu Jalli
B46: Hyderabad
B47: e-mail : rambabujalli@gmail.com
B48: website : | C48: www.jallisapp.com
